nohup: ignoring input
2025-03-30 19:17:36,080 - httpx - INFO - HTTP Request: POST https://api.telegram.org/bot7641317425:AAHfWDG6uHQZeG8BQ5JvuvjMFvLFgrqbh9Q/getMe "HTTP/1.1 200 OK"
2025-03-30 19:17:36,516 - httpx - INFO - HTTP Request: POST https://api.telegram.org/bot7641317425:AAHfWDG6uHQZeG8BQ5JvuvjMFvLFgrqbh9Q/deleteWebhook "HTTP/1.1 200 OK"
2025-03-30 19:17:36,520 - telegram.ext.Application - INFO - Application started
2025-03-30 19:17:47,580 - httpx - INFO - HTTP Request: POST https://api.telegram.org/bot7641317425:AAHfWDG6uHQZeG8BQ5JvuvjMFvLFgrqbh9Q/getUpdates "HTTP/1.1 200 OK"
2025-03-30 19:17:57,922 - httpx - INFO - HTTP Request: POST https://api.telegram.org/bot7641317425:AAHfWDG6uHQZeG8BQ5JvuvjMFvLFgrqbh9Q/getUpdates "HTTP/1.1 200 OK"
2025-03-30 19:18:08,264 - httpx - INFO - HTTP Request: POST https://api.telegram.org/bot7641317425:AAHfWDG6uHQZeG8BQ5JvuvjMFvLFgrqbh9Q/getUpdates "HTTP/1.1 200 OK"
2025-03-30 19:18:18,607 - httpx - INFO - HTTP Request: POST https://api.telegram.org/bot7641317425:AAHfWDG6uHQZeG8BQ5JvuvjMFvLFgrqbh9Q/getUpdates "HTTP/1.1 200 OK"
2025-03-30 19:18:25,877 - httpx - INFO - HTTP Request: POST https://api.telegram.org/bot7641317425:AAHfWDG6uHQZeG8BQ5JvuvjMFvLFgrqbh9Q/getUpdates "HTTP/1.1 200 OK"
2025-03-30 19:18:27,175 - httpx - INFO - HTTP Request: POST https://api.telegram.org/bot7641317425:AAHfWDG6uHQZeG8BQ5JvuvjMFvLFgrqbh9Q/sendMessage "HTTP/1.1 200 OK"
2025-03-30 19:18:27,821 - httpx - INFO - HTTP Request: POST https://api.telegram.org/bot7641317425:AAHfWDG6uHQZeG8BQ5JvuvjMFvLFgrqbh9Q/sendVideo "HTTP/1.1 200 OK"
2025-03-30 19:18:28,436 - httpx - INFO - HTTP Request: POST https://api.telegram.org/bot7641317425:AAHfWDG6uHQZeG8BQ5JvuvjMFvLFgrqbh9Q/sendMessage "HTTP/1.1 200 OK"
2025-03-30 19:18:36,323 - httpx - INFO - HTTP Request: POST https://api.telegram.org/bot7641317425:AAHfWDG6uHQZeG8BQ5JvuvjMFvLFgrqbh9Q/getUpdates "HTTP/1.1 200 OK"
2025-03-30 19:18:46,111 - httpx - INFO - HTTP Request: POST https://api.telegram.org/bot7641317425:AAHfWDG6uHQZeG8BQ5JvuvjMFvLFgrqbh9Q/getUpdates "HTTP/1.1 200 OK"
2025-03-30 19:18:47,302 - httpx - INFO - HTTP Request: POST https://api.telegram.org/bot7641317425:AAHfWDG6uHQZeG8BQ5JvuvjMFvLFgrqbh9Q/sendMessage "HTTP/1.1 200 OK"
2025-03-30 19:18:47,833 - httpx - INFO - HTTP Request: POST https://api.telegram.org/bot7641317425:AAHfWDG6uHQZeG8BQ5JvuvjMFvLFgrqbh9Q/sendVideo "HTTP/1.1 200 OK"
2025-03-30 19:18:48,354 - httpx - INFO - HTTP Request: POST https://api.telegram.org/bot7641317425:AAHfWDG6uHQZeG8BQ5JvuvjMFvLFgrqbh9Q/sendMessage "HTTP/1.1 200 OK"
2025-03-30 19:18:56,598 - httpx - INFO - HTTP Request: POST https://api.telegram.org/bot7641317425:AAHfWDG6uHQZeG8BQ5JvuvjMFvLFgrqbh9Q/getUpdates "HTTP/1.1 200 OK"
2025-03-30 19:18:59,976 - httpx - INFO - HTTP Request: POST https://api.telegram.org/bot7641317425:AAHfWDG6uHQZeG8BQ5JvuvjMFvLFgrqbh9Q/getUpdates "HTTP/1.1 200 OK"
2025-03-30 19:19:01,219 - httpx - INFO - HTTP Request: POST https://api.telegram.org/bot7641317425:AAHfWDG6uHQZeG8BQ5JvuvjMFvLFgrqbh9Q/sendMessage "HTTP/1.1 200 OK"
2025-03-30 19:19:01,778 - httpx - INFO - HTTP Request: POST https://api.telegram.org/bot7641317425:AAHfWDG6uHQZeG8BQ5JvuvjMFvLFgrqbh9Q/sendVideo "HTTP/1.1 200 OK"
2025-03-30 19:19:02,306 - httpx - INFO - HTTP Request: POST https://api.telegram.org/bot7641317425:AAHfWDG6uHQZeG8BQ5JvuvjMFvLFgrqbh9Q/sendMessage "HTTP/1.1 200 OK"
2025-03-30 19:19:04,278 - httpx - INFO - HTTP Request: POST https://api.telegram.org/bot7641317425:AAHfWDG6uHQZeG8BQ5JvuvjMFvLFgrqbh9Q/getUpdates "HTTP/1.1 200 OK"
2025-03-30 19:19:04,864 - httpx - INFO - HTTP Request: POST https://api.telegram.org/bot7641317425:AAHfWDG6uHQZeG8BQ5JvuvjMFvLFgrqbh9Q/sendMessage "HTTP/1.1 200 OK"
2025-03-30 19:19:06,734 - httpx - INFO - HTTP Request: POST https://api.telegram.org/bot7641317425:AAHfWDG6uHQZeG8BQ5JvuvjMFvLFgrqbh9Q/getUpdates "HTTP/1.1 200 OK"
2025-03-30 19:19:07,280 - httpx - INFO - HTTP Request: POST https://api.telegram.org/bot7641317425:AAHfWDG6uHQZeG8BQ5JvuvjMFvLFgrqbh9Q/answerCallbackQuery "HTTP/1.1 200 OK"
2025-03-30 19:19:07,962 - httpx - INFO - HTTP Request: POST https://api.telegram.org/bot7641317425:AAHfWDG6uHQZeG8BQ5JvuvjMFvLFgrqbh9Q/sendVideo "HTTP/1.1 200 OK"
2025-03-30 19:19:16,875 - httpx - INFO - HTTP Request: POST https://api.telegram.org/bot7641317425:AAHfWDG6uHQZeG8BQ5JvuvjMFvLFgrqbh9Q/getUpdates "HTTP/1.1 200 OK"
2025-03-30 19:19:18,120 - httpx - INFO - HTTP Request: POST https://api.telegram.org/bot7641317425:AAHfWDG6uHQZeG8BQ5JvuvjMFvLFgrqbh9Q/sendMessage "HTTP/1.1 200 OK"
2025-03-30 19:19:18,662 - httpx - INFO - HTTP Request: POST https://api.telegram.org/bot7641317425:AAHfWDG6uHQZeG8BQ5JvuvjMFvLFgrqbh9Q/sendVideo "HTTP/1.1 200 OK"
2025-03-30 19:19:19,201 - httpx - INFO - HTTP Request: POST https://api.telegram.org/bot7641317425:AAHfWDG6uHQZeG8BQ5JvuvjMFvLFgrqbh9Q/sendMessage "HTTP/1.1 200 OK"
2025-03-30 19:19:27,319 - httpx - INFO - HTTP Request: POST https://api.telegram.org/bot7641317425:AAHfWDG6uHQZeG8BQ5JvuvjMFvLFgrqbh9Q/getUpdates "HTTP/1.1 200 OK"
2025-03-30 19:19:37,662 - httpx - INFO - HTTP Request: POST https://api.telegram.org/bot7641317425:AAHfWDG6uHQZeG8BQ5JvuvjMFvLFgrqbh9Q/getUpdates "HTTP/1.1 200 OK"
2025-03-30 19:19:48,003 - httpx - INFO - HTTP Request: POST https://api.telegram.org/bot7641317425:AAHfWDG6uHQZeG8BQ5JvuvjMFvLFgrqbh9Q/getUpdates "HTTP/1.1 200 OK"
2025-03-30 19:19:58,346 - httpx - INFO - HTTP Request: POST https://api.telegram.org/bot7641317425:AAHfWDG6uHQZeG8BQ5JvuvjMFvLFgrqbh9Q/getUpdates "HTTP/1.1 200 OK"
2025-03-30 19:20:08,687 - httpx - INFO - HTTP Request: POST https://api.telegram.org/bot7641317425:AAHfWDG6uHQZeG8BQ5JvuvjMFvLFgrqbh9Q/getUpdates "HTTP/1.1 200 OK"
2025-03-30 19:20:19,133 - httpx - INFO - HTTP Request: POST https://api.telegram.org/bot7641317425:AAHfWDG6uHQZeG8BQ5JvuvjMFvLFgrqbh9Q/getUpdates "HTTP/1.1 200 OK"
2025-03-30 19:20:29,475 - httpx - INFO - HTTP Request: POST https://api.telegram.org/bot7641317425:AAHfWDG6uHQZeG8BQ5JvuvjMFvLFgrqbh9Q/getUpdates "HTTP/1.1 200 OK"
2025-03-30 19:20:33,367 - httpx - INFO - HTTP Request: POST https://api.telegram.org/bot7641317425:AAHfWDG6uHQZeG8BQ5JvuvjMFvLFgrqbh9Q/getUpdates "HTTP/1.1 200 OK"
2025-03-30 19:20:34,669 - httpx - INFO - HTTP Request: POST https://api.telegram.org/bot7641317425:AAHfWDG6uHQZeG8BQ5JvuvjMFvLFgrqbh9Q/sendMessage "HTTP/1.1 200 OK"
2025-03-30 19:20:35,201 - httpx - INFO - HTTP Request: POST https://api.telegram.org/bot7641317425:AAHfWDG6uHQZeG8BQ5JvuvjMFvLFgrqbh9Q/sendVideo "HTTP/1.1 200 OK"
2025-03-30 19:20:35,820 - httpx - INFO - HTTP Request: POST https://api.telegram.org/bot7641317425:AAHfWDG6uHQZeG8BQ5JvuvjMFvLFgrqbh9Q/sendMessage "HTTP/1.1 200 OK"
2025-03-30 19:20:43,812 - httpx - INFO - HTTP Request: POST https://api.telegram.org/bot7641317425:AAHfWDG6uHQZeG8BQ5JvuvjMFvLFgrqbh9Q/getUpdates "HTTP/1.1 200 OK"
2025-03-30 19:20:53,028 - httpx - INFO - HTTP Request: POST https://api.telegram.org/bot7641317425:AAHfWDG6uHQZeG8BQ5JvuvjMFvLFgrqbh9Q/getUpdates "HTTP/1.1 200 OK"
2025-03-30 19:20:54,249 - httpx - INFO - HTTP Request: POST https://api.telegram.org/bot7641317425:AAHfWDG6uHQZeG8BQ5JvuvjMFvLFgrqbh9Q/sendMessage "HTTP/1.1 200 OK"
2025-03-30 19:20:55,693 - httpx - INFO - HTTP Request: POST https://api.telegram.org/bot7641317425:AAHfWDG6uHQZeG8BQ5JvuvjMFvLFgrqbh9Q/getUpdates "HTTP/1.1 200 OK"
2025-03-30 19:20:56,220 - httpx - INFO - HTTP Request: POST https://api.telegram.org/bot7641317425:AAHfWDG6uHQZeG8BQ5JvuvjMFvLFgrqbh9Q/sendMessage "HTTP/1.1 200 OK"
2025-03-30 19:20:57,432 - httpx - INFO - HTTP Request: POST https://api.telegram.org/bot7641317425:AAHfWDG6uHQZeG8BQ5JvuvjMFvLFgrqbh9Q/getUpdates "HTTP/1.1 200 OK"
2025-03-30 19:20:57,944 - httpx - INFO - HTTP Request: POST https://api.telegram.org/bot7641317425:AAHfWDG6uHQZeG8BQ5JvuvjMFvLFgrqbh9Q/answerCallbackQuery "HTTP/1.1 200 OK"
2025-03-30 19:20:58,458 - httpx - INFO - HTTP Request: POST https://api.telegram.org/bot7641317425:AAHfWDG6uHQZeG8BQ5JvuvjMFvLFgrqbh9Q/sendVideo "HTTP/1.1 200 OK"
2025-03-30 19:21:07,773 - httpx - INFO - HTTP Request: POST https://api.telegram.org/bot7641317425:AAHfWDG6uHQZeG8BQ5JvuvjMFvLFgrqbh9Q/getUpdates "HTTP/1.1 200 OK"
2025-03-30 19:21:09,025 - httpx - INFO - HTTP Request: POST https://api.telegram.org/bot7641317425:AAHfWDG6uHQZeG8BQ5JvuvjMFvLFgrqbh9Q/sendMessage "HTTP/1.1 200 OK"
2025-03-30 19:21:09,622 - httpx - INFO - HTTP Request: POST https://api.telegram.org/bot7641317425:AAHfWDG6uHQZeG8BQ5JvuvjMFvLFgrqbh9Q/sendVideo "HTTP/1.1 200 OK"
2025-03-30 19:21:10,196 - httpx - INFO - HTTP Request: POST https://api.telegram.org/bot7641317425:AAHfWDG6uHQZeG8BQ5JvuvjMFvLFgrqbh9Q/sendMessage "HTTP/1.1 200 OK"
2025-03-30 19:21:16,272 - httpx - INFO - HTTP Request: POST https://api.telegram.org/bot7641317425:AAHfWDG6uHQZeG8BQ5JvuvjMFvLFgrqbh9Q/getUpdates "HTTP/1.1 200 OK"
2025-03-30 19:21:17,508 - httpx - INFO - HTTP Request: POST https://api.telegram.org/bot7641317425:AAHfWDG6uHQZeG8BQ5JvuvjMFvLFgrqbh9Q/sendMessage "HTTP/1.1 200 OK"
2025-03-30 19:21:18,057 - httpx - INFO - HTTP Request: POST https://api.telegram.org/bot7641317425:AAHfWDG6uHQZeG8BQ5JvuvjMFvLFgrqbh9Q/sendPhoto "HTTP/1.1 200 OK"
2025-03-30 19:21:26,714 - httpx - INFO - HTTP Request: POST https://api.telegram.org/bot7641317425:AAHfWDG6uHQZeG8BQ5JvuvjMFvLFgrqbh9Q/getUpdates "HTTP/1.1 200 OK"
2025-03-30 19:21:37,059 - httpx - INFO - HTTP Request: POST https://api.telegram.org/bot7641317425:AAHfWDG6uHQZeG8BQ5JvuvjMFvLFgrqbh9Q/getUpdates "HTTP/1.1 200 OK"
2025-03-30 19:21:47,402 - httpx - INFO - HTTP Request: POST https://api.telegram.org/bot7641317425:AAHfWDG6uHQZeG8BQ5JvuvjMFvLFgrqbh9Q/getUpdates "HTTP/1.1 200 OK"
2025-03-30 19:21:52,728 - httpx - INFO - HTTP Request: POST https://api.telegram.org/bot7641317425:AAHfWDG6uHQZeG8BQ5JvuvjMFvLFgrqbh9Q/getUpdates "HTTP/1.1 200 OK"
2025-03-30 19:21:54,028 - httpx - INFO - HTTP Request: POST https://api.telegram.org/bot7641317425:AAHfWDG6uHQZeG8BQ5JvuvjMFvLFgrqbh9Q/sendMessage "HTTP/1.1 200 OK"
2025-03-30 19:21:56,003 - httpx - INFO - HTTP Request: POST https://api.telegram.org/bot7641317425:AAHfWDG6uHQZeG8BQ5JvuvjMFvLFgrqbh9Q/getUpdates "HTTP/1.1 200 OK"
2025-03-30 19:21:56,511 - httpx - INFO - HTTP Request: POST https://api.telegram.org/bot7641317425:AAHfWDG6uHQZeG8BQ5JvuvjMFvLFgrqbh9Q/answerCallbackQuery "HTTP/1.1 200 OK"
2025-03-30 19:21:57,031 - httpx - INFO - HTTP Request: POST https://api.telegram.org/bot7641317425:AAHfWDG6uHQZeG8BQ5JvuvjMFvLFgrqbh9Q/sendVideo "HTTP/1.1 200 OK"
2025-03-30 19:21:58,360 - httpx - INFO - HTTP Request: POST https://api.telegram.org/bot7641317425:AAHfWDG6uHQZeG8BQ5JvuvjMFvLFgrqbh9Q/getUpdates "HTTP/1.1 200 OK"
2025-03-30 19:21:58,890 - httpx - INFO - HTTP Request: POST https://api.telegram.org/bot7641317425:AAHfWDG6uHQZeG8BQ5JvuvjMFvLFgrqbh9Q/answerCallbackQuery "HTTP/1.1 200 OK"
2025-03-30 19:21:59,452 - httpx - INFO - HTTP Request: POST https://api.telegram.org/bot7641317425:AAHfWDG6uHQZeG8BQ5JvuvjMFvLFgrqbh9Q/sendVideo "HTTP/1.1 200 OK"
2025-03-30 19:22:01,330 - httpx - INFO - HTTP Request: POST https://api.telegram.org/bot7641317425:AAHfWDG6uHQZeG8BQ5JvuvjMFvLFgrqbh9Q/getUpdates "HTTP/1.1 200 OK"
2025-03-30 19:22:01,876 - httpx - INFO - HTTP Request: POST https://api.telegram.org/bot7641317425:AAHfWDG6uHQZeG8BQ5JvuvjMFvLFgrqbh9Q/answerCallbackQuery "HTTP/1.1 200 OK"
2025-03-30 19:22:02,557 - httpx - INFO - HTTP Request: POST https://api.telegram.org/bot7641317425:AAHfWDG6uHQZeG8BQ5JvuvjMFvLFgrqbh9Q/sendVideo "HTTP/1.1 200 OK"
2025-03-30 19:22:06,447 - httpx - INFO - HTTP Request: POST https://api.telegram.org/bot7641317425:AAHfWDG6uHQZeG8BQ5JvuvjMFvLFgrqbh9Q/getUpdates "HTTP/1.1 200 OK"
2025-03-30 19:22:06,963 - httpx - INFO - HTTP Request: POST https://api.telegram.org/bot7641317425:AAHfWDG6uHQZeG8BQ5JvuvjMFvLFgrqbh9Q/answerCallbackQuery "HTTP/1.1 200 OK"
2025-03-30 19:22:07,489 - httpx - INFO - HTTP Request: POST https://api.telegram.org/bot7641317425:AAHfWDG6uHQZeG8BQ5JvuvjMFvLFgrqbh9Q/sendVideo "HTTP/1.1 200 OK"
2025-03-30 19:22:08,596 - httpx - INFO - HTTP Request: POST https://api.telegram.org/bot7641317425:AAHfWDG6uHQZeG8BQ5JvuvjMFvLFgrqbh9Q/getUpdates "HTTP/1.1 200 OK"
2025-03-30 19:22:09,100 - httpx - INFO - HTTP Request: POST https://api.telegram.org/bot7641317425:AAHfWDG6uHQZeG8BQ5JvuvjMFvLFgrqbh9Q/answerCallbackQuery "HTTP/1.1 200 OK"
2025-03-30 19:22:09,613 - httpx - INFO - HTTP Request: POST https://api.telegram.org/bot7641317425:AAHfWDG6uHQZeG8BQ5JvuvjMFvLFgrqbh9Q/sendVideo "HTTP/1.1 200 OK"
2025-03-30 19:22:10,192 - httpx - INFO - HTTP Request: POST https://api.telegram.org/bot7641317425:AAHfWDG6uHQZeG8BQ5JvuvjMFvLFgrqbh9Q/sendMessage "HTTP/1.1 200 OK"
2025-03-30 19:22:10,706 - httpx - INFO - HTTP Request: POST https://api.telegram.org/bot7641317425:AAHfWDG6uHQZeG8BQ5JvuvjMFvLFgrqbh9Q/sendMessage "HTTP/1.1 200 OK"
2025-03-30 19:22:11,217 - httpx - INFO - HTTP Request: POST https://api.telegram.org/bot7641317425:AAHfWDG6uHQZeG8BQ5JvuvjMFvLFgrqbh9Q/editMessageText "HTTP/1.1 200 OK"
2025-03-30 19:22:18,936 - httpx - INFO - HTTP Request: POST https://api.telegram.org/bot7641317425:AAHfWDG6uHQZeG8BQ5JvuvjMFvLFgrqbh9Q/getUpdates "HTTP/1.1 200 OK"
2025-03-30 19:22:29,260 - httpx - INFO - HTTP Request: POST https://api.telegram.org/bot7641317425:AAHfWDG6uHQZeG8BQ5JvuvjMFvLFgrqbh9Q/getUpdates "HTTP/1.1 200 OK"
2025-03-30 19:22:39,625 - httpx - INFO - HTTP Request: POST https://api.telegram.org/bot7641317425:AAHfWDG6uHQZeG8BQ5JvuvjMFvLFgrqbh9Q/getUpdates "HTTP/1.1 200 OK"
2025-03-30 19:22:44,748 - httpx - INFO - HTTP Request: POST https://api.telegram.org/bot7641317425:AAHfWDG6uHQZeG8BQ5JvuvjMFvLFgrqbh9Q/getUpdates "HTTP/1.1 200 OK"
2025-03-30 19:22:45,983 - httpx - INFO - HTTP Request: POST https://api.telegram.org/bot7641317425:AAHfWDG6uHQZeG8BQ5JvuvjMFvLFgrqbh9Q/sendMessage "HTTP/1.1 200 OK"
2025-03-30 19:22:47,717 - httpx - INFO - HTTP Request: POST https://api.telegram.org/bot7641317425:AAHfWDG6uHQZeG8BQ5JvuvjMFvLFgrqbh9Q/getUpdates "HTTP/1.1 200 OK"
2025-03-30 19:22:48,246 - httpx - INFO - HTTP Request: POST https://api.telegram.org/bot7641317425:AAHfWDG6uHQZeG8BQ5JvuvjMFvLFgrqbh9Q/sendMessage "HTTP/1.1 200 OK"
2025-03-30 19:22:49,355 - httpx - INFO - HTTP Request: POST https://api.telegram.org/bot7641317425:AAHfWDG6uHQZeG8BQ5JvuvjMFvLFgrqbh9Q/getUpdates "HTTP/1.1 200 OK"
2025-03-30 19:22:49,860 - httpx - INFO - HTTP Request: POST https://api.telegram.org/bot7641317425:AAHfWDG6uHQZeG8BQ5JvuvjMFvLFgrqbh9Q/answerCallbackQuery "HTTP/1.1 200 OK"
2025-03-30 19:22:50,404 - httpx - INFO - HTTP Request: POST https://api.telegram.org/bot7641317425:AAHfWDG6uHQZeG8BQ5JvuvjMFvLFgrqbh9Q/sendMessage "HTTP/1.1 200 OK"
2025-03-30 19:22:50,909 - httpx - INFO - HTTP Request: POST https://api.telegram.org/bot7641317425:AAHfWDG6uHQZeG8BQ5JvuvjMFvLFgrqbh9Q/editMessageText "HTTP/1.1 200 OK"
2025-03-30 19:22:52,735 - httpx - INFO - HTTP Request: POST https://api.telegram.org/bot7641317425:AAHfWDG6uHQZeG8BQ5JvuvjMFvLFgrqbh9Q/getUpdates "HTTP/1.1 200 OK"
2025-03-30 19:22:53,254 - httpx - INFO - HTTP Request: POST https://api.telegram.org/bot7641317425:AAHfWDG6uHQZeG8BQ5JvuvjMFvLFgrqbh9Q/sendMessage "HTTP/1.1 200 OK"
2025-03-30 19:22:54,374 - httpx - INFO - HTTP Request: POST https://api.telegram.org/bot7641317425:AAHfWDG6uHQZeG8BQ5JvuvjMFvLFgrqbh9Q/getUpdates "HTTP/1.1 200 OK"
2025-03-30 19:22:54,881 - httpx - INFO - HTTP Request: POST https://api.telegram.org/bot7641317425:AAHfWDG6uHQZeG8BQ5JvuvjMFvLFgrqbh9Q/answerCallbackQuery "HTTP/1.1 200 OK"
2025-03-30 19:22:55,385 - httpx - INFO - HTTP Request: POST https://api.telegram.org/bot7641317425:AAHfWDG6uHQZeG8BQ5JvuvjMFvLFgrqbh9Q/sendMessage "HTTP/1.1 200 OK"
2025-03-30 19:22:55,879 - httpx - INFO - HTTP Request: POST https://api.telegram.org/bot7641317425:AAHfWDG6uHQZeG8BQ5JvuvjMFvLFgrqbh9Q/editMessageText "HTTP/1.1 200 OK"
2025-03-30 19:23:03,667 - httpx - INFO - HTTP Request: POST https://api.telegram.org/bot7641317425:AAHfWDG6uHQZeG8BQ5JvuvjMFvLFgrqbh9Q/getUpdates "HTTP/1.1 200 OK"
2025-03-30 19:23:04,867 - httpx - INFO - HTTP Request: POST https://api.telegram.org/bot7641317425:AAHfWDG6uHQZeG8BQ5JvuvjMFvLFgrqbh9Q/answerCallbackQuery "HTTP/1.1 200 OK"
2025-03-30 19:23:04,873 - __main__ - ERROR - Error handling button press: invalid literal for int() with base 10: '_7942816218'
2025-03-30 19:23:05,385 - httpx - INFO - HTTP Request: POST https://api.telegram.org/bot7641317425:AAHfWDG6uHQZeG8BQ5JvuvjMFvLFgrqbh9Q/editMessageText "HTTP/1.1 200 OK"
2025-03-30 19:23:14,134 - httpx - INFO - HTTP Request: POST https://api.telegram.org/bot7641317425:AAHfWDG6uHQZeG8BQ5JvuvjMFvLFgrqbh9Q/getUpdates "HTTP/1.1 200 OK"
2025-03-30 19:23:22,941 - httpx - INFO - HTTP Request: POST https://api.telegram.org/bot7641317425:AAHfWDG6uHQZeG8BQ5JvuvjMFvLFgrqbh9Q/getUpdates "HTTP/1.1 200 OK"
2025-03-30 19:23:24,230 - httpx - INFO - HTTP Request: POST https://api.telegram.org/bot7641317425:AAHfWDG6uHQZeG8BQ5JvuvjMFvLFgrqbh9Q/sendMessage "HTTP/1.1 200 OK"
2025-03-30 19:23:25,363 - httpx - INFO - HTTP Request: POST https://api.telegram.org/bot7641317425:AAHfWDG6uHQZeG8BQ5JvuvjMFvLFgrqbh9Q/getUpdates "HTTP/1.1 200 OK"
2025-03-30 19:23:25,879 - httpx - INFO - HTTP Request: POST https://api.telegram.org/bot7641317425:AAHfWDG6uHQZeG8BQ5JvuvjMFvLFgrqbh9Q/answerCallbackQuery "HTTP/1.1 200 OK"
2025-03-30 19:23:26,397 - httpx - INFO - HTTP Request: POST https://api.telegram.org/bot7641317425:AAHfWDG6uHQZeG8BQ5JvuvjMFvLFgrqbh9Q/sendMessage "HTTP/1.1 200 OK"
2025-03-30 19:23:26,908 - httpx - INFO - HTTP Request: POST https://api.telegram.org/bot7641317425:AAHfWDG6uHQZeG8BQ5JvuvjMFvLFgrqbh9Q/editMessageText "HTTP/1.1 200 OK"
2025-03-30 19:23:29,702 - httpx - INFO - HTTP Request: POST https://api.telegram.org/bot7641317425:AAHfWDG6uHQZeG8BQ5JvuvjMFvLFgrqbh9Q/getUpdates "HTTP/1.1 200 OK"
2025-03-30 19:23:30,231 - httpx - INFO - HTTP Request: POST https://api.telegram.org/bot7641317425:AAHfWDG6uHQZeG8BQ5JvuvjMFvLFgrqbh9Q/answerCallbackQuery "HTTP/1.1 200 OK"
2025-03-30 19:23:30,757 - httpx - INFO - HTTP Request: POST https://api.telegram.org/bot7641317425:AAHfWDG6uHQZeG8BQ5JvuvjMFvLFgrqbh9Q/sendMessage "HTTP/1.1 200 OK"
2025-03-30 19:23:31,132 - httpx - INFO - HTTP Request: POST https://api.telegram.org/bot7641317425:AAHfWDG6uHQZeG8BQ5JvuvjMFvLFgrqbh9Q/editMessageText "HTTP/1.1 400 Bad Request"
2025-03-30 19:23:31,138 - __main__ - ERROR - Error editing approval message: There is no text in the message to edit
2025-03-30 19:23:31,749 - httpx - INFO - HTTP Request: POST https://api.telegram.org/bot7641317425:AAHfWDG6uHQZeG8BQ5JvuvjMFvLFgrqbh9Q/sendMessage "HTTP/1.1 200 OK"
2025-03-30 19:23:40,250 - httpx - INFO - HTTP Request: POST https://api.telegram.org/bot7641317425:AAHfWDG6uHQZeG8BQ5JvuvjMFvLFgrqbh9Q/getUpdates "HTTP/1.1 200 OK"
2025-03-30 19:23:50,591 - httpx - INFO - HTTP Request: POST https://api.telegram.org/bot7641317425:AAHfWDG6uHQZeG8BQ5JvuvjMFvLFgrqbh9Q/getUpdates "HTTP/1.1 200 OK"
2025-03-30 19:23:54,790 - httpx - INFO - HTTP Request: POST https://api.telegram.org/bot7641317425:AAHfWDG6uHQZeG8BQ5JvuvjMFvLFgrqbh9Q/getUpdates "HTTP/1.1 200 OK"
2025-03-30 19:23:56,046 - httpx - INFO - HTTP Request: POST https://api.telegram.org/bot7641317425:AAHfWDG6uHQZeG8BQ5JvuvjMFvLFgrqbh9Q/answerCallbackQuery "HTTP/1.1 200 OK"
2025-03-30 19:23:56,559 - httpx - INFO - HTTP Request: POST https://api.telegram.org/bot7641317425:AAHfWDG6uHQZeG8BQ5JvuvjMFvLFgrqbh9Q/sendMessage "HTTP/1.1 200 OK"
2025-03-30 19:23:56,941 - httpx - INFO - HTTP Request: POST https://api.telegram.org/bot7641317425:AAHfWDG6uHQZeG8BQ5JvuvjMFvLFgrqbh9Q/editMessageText "HTTP/1.1 400 Bad Request"
2025-03-30 19:23:56,947 - __main__ - ERROR - Error editing rejection message: There is no text in the message to edit
2025-03-30 19:23:57,557 - httpx - INFO - HTTP Request: POST https://api.telegram.org/bot7641317425:AAHfWDG6uHQZeG8BQ5JvuvjMFvLFgrqbh9Q/sendMessage "HTTP/1.1 200 OK"
2025-03-30 19:24:05,228 - httpx - INFO - HTTP Request: POST https://api.telegram.org/bot7641317425:AAHfWDG6uHQZeG8BQ5JvuvjMFvLFgrqbh9Q/getUpdates "HTTP/1.1 200 OK"
2025-03-30 19:24:15,576 - httpx - INFO - HTTP Request: POST https://api.telegram.org/bot7641317425:AAHfWDG6uHQZeG8BQ5JvuvjMFvLFgrqbh9Q/getUpdates "HTTP/1.1 200 OK"
2025-03-30 19:24:16,600 - httpx - INFO - HTTP Request: POST https://api.telegram.org/bot7641317425:AAHfWDG6uHQZeG8BQ5JvuvjMFvLFgrqbh9Q/getUpdates "HTTP/1.1 200 OK"
2025-03-30 19:24:17,874 - httpx - INFO - HTTP Request: POST https://api.telegram.org/bot7641317425:AAHfWDG6uHQZeG8BQ5JvuvjMFvLFgrqbh9Q/sendMessage "HTTP/1.1 200 OK"
2025-03-30 19:24:18,421 - httpx - INFO - HTTP Request: POST https://api.telegram.org/bot7641317425:AAHfWDG6uHQZeG8BQ5JvuvjMFvLFgrqbh9Q/sendPhoto "HTTP/1.1 200 OK"
2025-03-30 19:24:21,496 - httpx - INFO - HTTP Request: POST https://api.telegram.org/bot7641317425:AAHfWDG6uHQZeG8BQ5JvuvjMFvLFgrqbh9Q/getUpdates "HTTP/1.1 200 OK"
2025-03-30 19:24:21,983 - httpx - INFO - HTTP Request: POST https://api.telegram.org/bot7641317425:AAHfWDG6uHQZeG8BQ5JvuvjMFvLFgrqbh9Q/answerCallbackQuery "HTTP/1.1 200 OK"
2025-03-30 19:24:22,541 - httpx - INFO - HTTP Request: POST https://api.telegram.org/bot7641317425:AAHfWDG6uHQZeG8BQ5JvuvjMFvLFgrqbh9Q/sendMessage "HTTP/1.1 200 OK"
2025-03-30 19:24:22,863 - httpx - INFO - HTTP Request: POST https://api.telegram.org/bot7641317425:AAHfWDG6uHQZeG8BQ5JvuvjMFvLFgrqbh9Q/editMessageText "HTTP/1.1 400 Bad Request"
2025-03-30 19:24:22,868 - __main__ - ERROR - Error editing rejection message: There is no text in the message to edit
2025-03-30 19:24:23,367 - httpx - INFO - HTTP Request: POST https://api.telegram.org/bot7641317425:AAHfWDG6uHQZeG8BQ5JvuvjMFvLFgrqbh9Q/sendMessage "HTTP/1.1 200 OK"
2025-03-30 19:24:36,552 - __main__ - ERROR - Exception while handling update:
Traceback (most recent call last):
  File "/data/data/com.termux/files/usr/lib/python3.12/site-packages/httpx/_transports/default.py", line 101, in map_httpcore_exceptions
    yield
  File "/data/data/com.termux/files/usr/lib/python3.12/site-packages/httpx/_transports/default.py", line 394, in handle_async_request
    resp = await self._pool.handle_async_request(req)
           ^^^^^^^^^^^^^^^^^^^^^^^^^^^^^^^^^^^^^^^^^^
  File "/data/data/com.termux/files/usr/lib/python3.12/site-packages/httpcore/_async/connection_pool.py", line 256, in handle_async_request
    raise exc from None
  File "/data/data/com.termux/files/usr/lib/python3.12/site-packages/httpcore/_async/connection_pool.py", line 236, in handle_async_request
    response = await connection.handle_async_request(
               ^^^^^^^^^^^^^^^^^^^^^^^^^^^^^^^^^^^^^^
  File "/data/data/com.termux/files/usr/lib/python3.12/site-packages/httpcore/_async/connection.py", line 101, in handle_async_request
    raise exc
  File "/data/data/com.termux/files/usr/lib/python3.12/site-packages/httpcore/_async/connection.py", line 78, in handle_async_request
    stream = await self._connect(request)
             ^^^^^^^^^^^^^^^^^^^^^^^^^^^^
  File "/data/data/com.termux/files/usr/lib/python3.12/site-packages/httpcore/_async/connection.py", line 124, in _connect
    stream = await self._network_backend.connect_tcp(**kwargs)
             ^^^^^^^^^^^^^^^^^^^^^^^^^^^^^^^^^^^^^^^^^^^^^^^^^
  File "/data/data/com.termux/files/usr/lib/python3.12/site-packages/httpcore/_backends/auto.py", line 31, in connect_tcp
    return await self._backend.connect_tcp(
           ^^^^^^^^^^^^^^^^^^^^^^^^^^^^^^^^
  File "/data/data/com.termux/files/usr/lib/python3.12/site-packages/httpcore/_backends/anyio.py", line 113, in connect_tcp
    with map_exceptions(exc_map):
         ^^^^^^^^^^^^^^^^^^^^^^^
  File "/data/data/com.termux/files/usr/lib/python3.12/contextlib.py", line 158, in __exit__
    self.gen.throw(value)
  File "/data/data/com.termux/files/usr/lib/python3.12/site-packages/httpcore/_exceptions.py", line 14, in map_exceptions
    raise to_exc(exc) from exc
httpcore.ConnectError: All connection attempts failed

The above exception was the direct cause of the following exception:

Traceback (most recent call last):
  File "/data/data/com.termux/files/usr/lib/python3.12/site-packages/telegram/request/_httpxrequest.py", line 277, in do_request
    res = await self._client.request(
          ^^^^^^^^^^^^^^^^^^^^^^^^^^^
  File "/data/data/com.termux/files/usr/lib/python3.12/site-packages/httpx/_client.py", line 1540, in request
    return await self.send(request, auth=auth, follow_redirects=follow_redirects)
           ^^^^^^^^^^^^^^^^^^^^^^^^^^^^^^^^^^^^^^^^^^^^^^^^^^^^^^^^^^^^^^^^^^^^^^
  File "/data/data/com.termux/files/usr/lib/python3.12/site-packages/httpx/_client.py", line 1629, in send
    response = await self._send_handling_auth(
               ^^^^^^^^^^^^^^^^^^^^^^^^^^^^^^^
  File "/data/data/com.termux/files/usr/lib/python3.12/site-packages/httpx/_client.py", line 1657, in _send_handling_auth
    response = await self._send_handling_redirects(
               ^^^^^^^^^^^^^^^^^^^^^^^^^^^^^^^^^^^^
  File "/data/data/com.termux/files/usr/lib/python3.12/site-packages/httpx/_client.py", line 1694, in _send_handling_redirects
    response = await self._send_single_request(request)
               ^^^^^^^^^^^^^^^^^^^^^^^^^^^^^^^^^^^^^^^^
  File "/data/data/com.termux/files/usr/lib/python3.12/site-packages/httpx/_client.py", line 1730, in _send_single_request
    response = await transport.handle_async_request(request)
               ^^^^^^^^^^^^^^^^^^^^^^^^^^^^^^^^^^^^^^^^^^^^^
  File "/data/data/com.termux/files/usr/lib/python3.12/site-packages/httpx/_transports/default.py", line 393, in handle_async_request
    with map_httpcore_exceptions():
         ^^^^^^^^^^^^^^^^^^^^^^^^^
  File "/data/data/com.termux/files/usr/lib/python3.12/contextlib.py", line 158, in __exit__
    self.gen.throw(value)
  File "/data/data/com.termux/files/usr/lib/python3.12/site-packages/httpx/_transports/default.py", line 118, in map_httpcore_exceptions
    raise mapped_exc(message) from exc
httpx.ConnectError: All connection attempts failed

The above exception was the direct cause of the following exception:

Traceback (most recent call last):
  File "/data/data/com.termux/files/usr/lib/python3.12/site-packages/telegram/ext/_utils/networkloop.py", line 115, in network_retry_loop
    if not await do_action():
           ^^^^^^^^^^^^^^^^^
  File "/data/data/com.termux/files/usr/lib/python3.12/site-packages/telegram/ext/_utils/networkloop.py", line 108, in do_action
    return action_cb_task.result()
           ^^^^^^^^^^^^^^^^^^^^^^^
  File "/data/data/com.termux/files/usr/lib/python3.12/site-packages/telegram/ext/_updater.py", line 335, in polling_action_cb
    updates = await self.bot.get_updates(
              ^^^^^^^^^^^^^^^^^^^^^^^^^^^
  File "/data/data/com.termux/files/usr/lib/python3.12/site-packages/telegram/ext/_extbot.py", line 658, in get_updates
    updates = await super().get_updates(
              ^^^^^^^^^^^^^^^^^^^^^^^^^^
  File "/data/data/com.termux/files/usr/lib/python3.12/site-packages/telegram/_bot.py", line 4593, in get_updates
    await self._post(
  File "/data/data/com.termux/files/usr/lib/python3.12/site-packages/telegram/_bot.py", line 691, in _post
    return await self._do_post(
           ^^^^^^^^^^^^^^^^^^^^
  File "/data/data/com.termux/files/usr/lib/python3.12/site-packages/telegram/ext/_extbot.py", line 362, in _do_post
    return await super()._do_post(
           ^^^^^^^^^^^^^^^^^^^^^^^
  File "/data/data/com.termux/files/usr/lib/python3.12/site-packages/telegram/_bot.py", line 720, in _do_post
    result = await request.post(
             ^^^^^^^^^^^^^^^^^^^
  File "/data/data/com.termux/files/usr/lib/python3.12/site-packages/telegram/request/_baserequest.py", line 197, in post
    result = await self._request_wrapper(
             ^^^^^^^^^^^^^^^^^^^^^^^^^^^^
  File "/data/data/com.termux/files/usr/lib/python3.12/site-packages/telegram/request/_baserequest.py", line 304, in _request_wrapper
    code, payload = await self.do_request(
                    ^^^^^^^^^^^^^^^^^^^^^^
  File "/data/data/com.termux/files/usr/lib/python3.12/site-packages/telegram/request/_httpxrequest.py", line 301, in do_request
    raise NetworkError(f"httpx.{err.__class__.__name__}: {err}") from err
telegram.error.NetworkError: httpx.ConnectError: All connection attempts failed
2025-03-30 19:24:37,563 - __main__ - ERROR - Exception while handling update:
Traceback (most recent call last):
  File "/data/data/com.termux/files/usr/lib/python3.12/site-packages/httpx/_transports/default.py", line 101, in map_httpcore_exceptions
    yield
  File "/data/data/com.termux/files/usr/lib/python3.12/site-packages/httpx/_transports/default.py", line 394, in handle_async_request
    resp = await self._pool.handle_async_request(req)
           ^^^^^^^^^^^^^^^^^^^^^^^^^^^^^^^^^^^^^^^^^^
  File "/data/data/com.termux/files/usr/lib/python3.12/site-packages/httpcore/_async/connection_pool.py", line 256, in handle_async_request
    raise exc from None
  File "/data/data/com.termux/files/usr/lib/python3.12/site-packages/httpcore/_async/connection_pool.py", line 236, in handle_async_request
    response = await connection.handle_async_request(
               ^^^^^^^^^^^^^^^^^^^^^^^^^^^^^^^^^^^^^^
  File "/data/data/com.termux/files/usr/lib/python3.12/site-packages/httpcore/_async/connection.py", line 101, in handle_async_request
    raise exc
  File "/data/data/com.termux/files/usr/lib/python3.12/site-packages/httpcore/_async/connection.py", line 78, in handle_async_request
    stream = await self._connect(request)
             ^^^^^^^^^^^^^^^^^^^^^^^^^^^^
  File "/data/data/com.termux/files/usr/lib/python3.12/site-packages/httpcore/_async/connection.py", line 124, in _connect
    stream = await self._network_backend.connect_tcp(**kwargs)
             ^^^^^^^^^^^^^^^^^^^^^^^^^^^^^^^^^^^^^^^^^^^^^^^^^
  File "/data/data/com.termux/files/usr/lib/python3.12/site-packages/httpcore/_backends/auto.py", line 31, in connect_tcp
    return await self._backend.connect_tcp(
           ^^^^^^^^^^^^^^^^^^^^^^^^^^^^^^^^
  File "/data/data/com.termux/files/usr/lib/python3.12/site-packages/httpcore/_backends/anyio.py", line 113, in connect_tcp
    with map_exceptions(exc_map):
         ^^^^^^^^^^^^^^^^^^^^^^^
  File "/data/data/com.termux/files/usr/lib/python3.12/contextlib.py", line 158, in __exit__
    self.gen.throw(value)
  File "/data/data/com.termux/files/usr/lib/python3.12/site-packages/httpcore/_exceptions.py", line 14, in map_exceptions
    raise to_exc(exc) from exc
httpcore.ConnectError: [Errno 7] No address associated with hostname

The above exception was the direct cause of the following exception:

Traceback (most recent call last):
  File "/data/data/com.termux/files/usr/lib/python3.12/site-packages/telegram/request/_httpxrequest.py", line 277, in do_request
    res = await self._client.request(
          ^^^^^^^^^^^^^^^^^^^^^^^^^^^
  File "/data/data/com.termux/files/usr/lib/python3.12/site-packages/httpx/_client.py", line 1540, in request
    return await self.send(request, auth=auth, follow_redirects=follow_redirects)
           ^^^^^^^^^^^^^^^^^^^^^^^^^^^^^^^^^^^^^^^^^^^^^^^^^^^^^^^^^^^^^^^^^^^^^^
  File "/data/data/com.termux/files/usr/lib/python3.12/site-packages/httpx/_client.py", line 1629, in send
    response = await self._send_handling_auth(
               ^^^^^^^^^^^^^^^^^^^^^^^^^^^^^^^
  File "/data/data/com.termux/files/usr/lib/python3.12/site-packages/httpx/_client.py", line 1657, in _send_handling_auth
    response = await self._send_handling_redirects(
               ^^^^^^^^^^^^^^^^^^^^^^^^^^^^^^^^^^^^
  File "/data/data/com.termux/files/usr/lib/python3.12/site-packages/httpx/_client.py", line 1694, in _send_handling_redirects
    response = await self._send_single_request(request)
               ^^^^^^^^^^^^^^^^^^^^^^^^^^^^^^^^^^^^^^^^
  File "/data/data/com.termux/files/usr/lib/python3.12/site-packages/httpx/_client.py", line 1730, in _send_single_request
    response = await transport.handle_async_request(request)
               ^^^^^^^^^^^^^^^^^^^^^^^^^^^^^^^^^^^^^^^^^^^^^
  File "/data/data/com.termux/files/usr/lib/python3.12/site-packages/httpx/_transports/default.py", line 393, in handle_async_request
    with map_httpcore_exceptions():
         ^^^^^^^^^^^^^^^^^^^^^^^^^
  File "/data/data/com.termux/files/usr/lib/python3.12/contextlib.py", line 158, in __exit__
    self.gen.throw(value)
  File "/data/data/com.termux/files/usr/lib/python3.12/site-packages/httpx/_transports/default.py", line 118, in map_httpcore_exceptions
    raise mapped_exc(message) from exc
httpx.ConnectError: [Errno 7] No address associated with hostname

The above exception was the direct cause of the following exception:

Traceback (most recent call last):
  File "/data/data/com.termux/files/usr/lib/python3.12/site-packages/telegram/ext/_utils/networkloop.py", line 115, in network_retry_loop
    if not await do_action():
           ^^^^^^^^^^^^^^^^^
  File "/data/data/com.termux/files/usr/lib/python3.12/site-packages/telegram/ext/_utils/networkloop.py", line 108, in do_action
    return action_cb_task.result()
           ^^^^^^^^^^^^^^^^^^^^^^^
  File "/data/data/com.termux/files/usr/lib/python3.12/site-packages/telegram/ext/_updater.py", line 335, in polling_action_cb
    updates = await self.bot.get_updates(
              ^^^^^^^^^^^^^^^^^^^^^^^^^^^
  File "/data/data/com.termux/files/usr/lib/python3.12/site-packages/telegram/ext/_extbot.py", line 658, in get_updates
    updates = await super().get_updates(
              ^^^^^^^^^^^^^^^^^^^^^^^^^^
  File "/data/data/com.termux/files/usr/lib/python3.12/site-packages/telegram/_bot.py", line 4593, in get_updates
    await self._post(
  File "/data/data/com.termux/files/usr/lib/python3.12/site-packages/telegram/_bot.py", line 691, in _post
    return await self._do_post(
           ^^^^^^^^^^^^^^^^^^^^
  File "/data/data/com.termux/files/usr/lib/python3.12/site-packages/telegram/ext/_extbot.py", line 362, in _do_post
    return await super()._do_post(
           ^^^^^^^^^^^^^^^^^^^^^^^
  File "/data/data/com.termux/files/usr/lib/python3.12/site-packages/telegram/_bot.py", line 720, in _do_post
    result = await request.post(
             ^^^^^^^^^^^^^^^^^^^
  File "/data/data/com.termux/files/usr/lib/python3.12/site-packages/telegram/request/_baserequest.py", line 197, in post
    result = await self._request_wrapper(
             ^^^^^^^^^^^^^^^^^^^^^^^^^^^^
  File "/data/data/com.termux/files/usr/lib/python3.12/site-packages/telegram/request/_baserequest.py", line 304, in _request_wrapper
    code, payload = await self.do_request(
                    ^^^^^^^^^^^^^^^^^^^^^^
  File "/data/data/com.termux/files/usr/lib/python3.12/site-packages/telegram/request/_httpxrequest.py", line 301, in do_request
    raise NetworkError(f"httpx.{err.__class__.__name__}: {err}") from err
telegram.error.NetworkError: httpx.ConnectError: [Errno 7] No address associated with hostname
2025-03-30 19:24:39,088 - __main__ - ERROR - Exception while handling update:
Traceback (most recent call last):
  File "/data/data/com.termux/files/usr/lib/python3.12/site-packages/httpx/_transports/default.py", line 101, in map_httpcore_exceptions
    yield
  File "/data/data/com.termux/files/usr/lib/python3.12/site-packages/httpx/_transports/default.py", line 394, in handle_async_request
    resp = await self._pool.handle_async_request(req)
           ^^^^^^^^^^^^^^^^^^^^^^^^^^^^^^^^^^^^^^^^^^
  File "/data/data/com.termux/files/usr/lib/python3.12/site-packages/httpcore/_async/connection_pool.py", line 256, in handle_async_request
    raise exc from None
  File "/data/data/com.termux/files/usr/lib/python3.12/site-packages/httpcore/_async/connection_pool.py", line 236, in handle_async_request
    response = await connection.handle_async_request(
               ^^^^^^^^^^^^^^^^^^^^^^^^^^^^^^^^^^^^^^
  File "/data/data/com.termux/files/usr/lib/python3.12/site-packages/httpcore/_async/connection.py", line 101, in handle_async_request
    raise exc
  File "/data/data/com.termux/files/usr/lib/python3.12/site-packages/httpcore/_async/connection.py", line 78, in handle_async_request
    stream = await self._connect(request)
             ^^^^^^^^^^^^^^^^^^^^^^^^^^^^
  File "/data/data/com.termux/files/usr/lib/python3.12/site-packages/httpcore/_async/connection.py", line 124, in _connect
    stream = await self._network_backend.connect_tcp(**kwargs)
             ^^^^^^^^^^^^^^^^^^^^^^^^^^^^^^^^^^^^^^^^^^^^^^^^^
  File "/data/data/com.termux/files/usr/lib/python3.12/site-packages/httpcore/_backends/auto.py", line 31, in connect_tcp
    return await self._backend.connect_tcp(
           ^^^^^^^^^^^^^^^^^^^^^^^^^^^^^^^^
  File "/data/data/com.termux/files/usr/lib/python3.12/site-packages/httpcore/_backends/anyio.py", line 113, in connect_tcp
    with map_exceptions(exc_map):
         ^^^^^^^^^^^^^^^^^^^^^^^
  File "/data/data/com.termux/files/usr/lib/python3.12/contextlib.py", line 158, in __exit__
    self.gen.throw(value)
  File "/data/data/com.termux/files/usr/lib/python3.12/site-packages/httpcore/_exceptions.py", line 14, in map_exceptions
    raise to_exc(exc) from exc
httpcore.ConnectError: [Errno 7] No address associated with hostname

The above exception was the direct cause of the following exception:

Traceback (most recent call last):
  File "/data/data/com.termux/files/usr/lib/python3.12/site-packages/telegram/request/_httpxrequest.py", line 277, in do_request
    res = await self._client.request(
          ^^^^^^^^^^^^^^^^^^^^^^^^^^^
  File "/data/data/com.termux/files/usr/lib/python3.12/site-packages/httpx/_client.py", line 1540, in request
    return await self.send(request, auth=auth, follow_redirects=follow_redirects)
           ^^^^^^^^^^^^^^^^^^^^^^^^^^^^^^^^^^^^^^^^^^^^^^^^^^^^^^^^^^^^^^^^^^^^^^
  File "/data/data/com.termux/files/usr/lib/python3.12/site-packages/httpx/_client.py", line 1629, in send
    response = await self._send_handling_auth(
               ^^^^^^^^^^^^^^^^^^^^^^^^^^^^^^^
  File "/data/data/com.termux/files/usr/lib/python3.12/site-packages/httpx/_client.py", line 1657, in _send_handling_auth
    response = await self._send_handling_redirects(
               ^^^^^^^^^^^^^^^^^^^^^^^^^^^^^^^^^^^^
  File "/data/data/com.termux/files/usr/lib/python3.12/site-packages/httpx/_client.py", line 1694, in _send_handling_redirects
    response = await self._send_single_request(request)
               ^^^^^^^^^^^^^^^^^^^^^^^^^^^^^^^^^^^^^^^^
  File "/data/data/com.termux/files/usr/lib/python3.12/site-packages/httpx/_client.py", line 1730, in _send_single_request
    response = await transport.handle_async_request(request)
               ^^^^^^^^^^^^^^^^^^^^^^^^^^^^^^^^^^^^^^^^^^^^^
  File "/data/data/com.termux/files/usr/lib/python3.12/site-packages/httpx/_transports/default.py", line 393, in handle_async_request
    with map_httpcore_exceptions():
         ^^^^^^^^^^^^^^^^^^^^^^^^^
  File "/data/data/com.termux/files/usr/lib/python3.12/contextlib.py", line 158, in __exit__
    self.gen.throw(value)
  File "/data/data/com.termux/files/usr/lib/python3.12/site-packages/httpx/_transports/default.py", line 118, in map_httpcore_exceptions
    raise mapped_exc(message) from exc
httpx.ConnectError: [Errno 7] No address associated with hostname

The above exception was the direct cause of the following exception:

Traceback (most recent call last):
  File "/data/data/com.termux/files/usr/lib/python3.12/site-packages/telegram/ext/_utils/networkloop.py", line 115, in network_retry_loop
    if not await do_action():
           ^^^^^^^^^^^^^^^^^
  File "/data/data/com.termux/files/usr/lib/python3.12/site-packages/telegram/ext/_utils/networkloop.py", line 108, in do_action
    return action_cb_task.result()
           ^^^^^^^^^^^^^^^^^^^^^^^
  File "/data/data/com.termux/files/usr/lib/python3.12/site-packages/telegram/ext/_updater.py", line 335, in polling_action_cb
    updates = await self.bot.get_updates(
              ^^^^^^^^^^^^^^^^^^^^^^^^^^^
  File "/data/data/com.termux/files/usr/lib/python3.12/site-packages/telegram/ext/_extbot.py", line 658, in get_updates
    updates = await super().get_updates(
              ^^^^^^^^^^^^^^^^^^^^^^^^^^
  File "/data/data/com.termux/files/usr/lib/python3.12/site-packages/telegram/_bot.py", line 4593, in get_updates
    await self._post(
  File "/data/data/com.termux/files/usr/lib/python3.12/site-packages/telegram/_bot.py", line 691, in _post
    return await self._do_post(
           ^^^^^^^^^^^^^^^^^^^^
  File "/data/data/com.termux/files/usr/lib/python3.12/site-packages/telegram/ext/_extbot.py", line 362, in _do_post
    return await super()._do_post(
           ^^^^^^^^^^^^^^^^^^^^^^^
  File "/data/data/com.termux/files/usr/lib/python3.12/site-packages/telegram/_bot.py", line 720, in _do_post
    result = await request.post(
             ^^^^^^^^^^^^^^^^^^^
  File "/data/data/com.termux/files/usr/lib/python3.12/site-packages/telegram/request/_baserequest.py", line 197, in post
    result = await self._request_wrapper(
             ^^^^^^^^^^^^^^^^^^^^^^^^^^^^
  File "/data/data/com.termux/files/usr/lib/python3.12/site-packages/telegram/request/_baserequest.py", line 304, in _request_wrapper
    code, payload = await self.do_request(
                    ^^^^^^^^^^^^^^^^^^^^^^
  File "/data/data/com.termux/files/usr/lib/python3.12/site-packages/telegram/request/_httpxrequest.py", line 301, in do_request
    raise NetworkError(f"httpx.{err.__class__.__name__}: {err}") from err
telegram.error.NetworkError: httpx.ConnectError: [Errno 7] No address associated with hostname
2025-03-30 19:24:41,356 - __main__ - ERROR - Exception while handling update:
Traceback (most recent call last):
  File "/data/data/com.termux/files/usr/lib/python3.12/site-packages/httpx/_transports/default.py", line 101, in map_httpcore_exceptions
    yield
  File "/data/data/com.termux/files/usr/lib/python3.12/site-packages/httpx/_transports/default.py", line 394, in handle_async_request
    resp = await self._pool.handle_async_request(req)
           ^^^^^^^^^^^^^^^^^^^^^^^^^^^^^^^^^^^^^^^^^^
  File "/data/data/com.termux/files/usr/lib/python3.12/site-packages/httpcore/_async/connection_pool.py", line 256, in handle_async_request
    raise exc from None
  File "/data/data/com.termux/files/usr/lib/python3.12/site-packages/httpcore/_async/connection_pool.py", line 236, in handle_async_request
    response = await connection.handle_async_request(
               ^^^^^^^^^^^^^^^^^^^^^^^^^^^^^^^^^^^^^^
  File "/data/data/com.termux/files/usr/lib/python3.12/site-packages/httpcore/_async/connection.py", line 101, in handle_async_request
    raise exc
  File "/data/data/com.termux/files/usr/lib/python3.12/site-packages/httpcore/_async/connection.py", line 78, in handle_async_request
    stream = await self._connect(request)
             ^^^^^^^^^^^^^^^^^^^^^^^^^^^^
  File "/data/data/com.termux/files/usr/lib/python3.12/site-packages/httpcore/_async/connection.py", line 124, in _connect
    stream = await self._network_backend.connect_tcp(**kwargs)
             ^^^^^^^^^^^^^^^^^^^^^^^^^^^^^^^^^^^^^^^^^^^^^^^^^
  File "/data/data/com.termux/files/usr/lib/python3.12/site-packages/httpcore/_backends/auto.py", line 31, in connect_tcp
    return await self._backend.connect_tcp(
           ^^^^^^^^^^^^^^^^^^^^^^^^^^^^^^^^
  File "/data/data/com.termux/files/usr/lib/python3.12/site-packages/httpcore/_backends/anyio.py", line 113, in connect_tcp
    with map_exceptions(exc_map):
         ^^^^^^^^^^^^^^^^^^^^^^^
  File "/data/data/com.termux/files/usr/lib/python3.12/contextlib.py", line 158, in __exit__
    self.gen.throw(value)
  File "/data/data/com.termux/files/usr/lib/python3.12/site-packages/httpcore/_exceptions.py", line 14, in map_exceptions
    raise to_exc(exc) from exc
httpcore.ConnectError: [Errno 7] No address associated with hostname

The above exception was the direct cause of the following exception:

Traceback (most recent call last):
  File "/data/data/com.termux/files/usr/lib/python3.12/site-packages/telegram/request/_httpxrequest.py", line 277, in do_request
    res = await self._client.request(
          ^^^^^^^^^^^^^^^^^^^^^^^^^^^
  File "/data/data/com.termux/files/usr/lib/python3.12/site-packages/httpx/_client.py", line 1540, in request
    return await self.send(request, auth=auth, follow_redirects=follow_redirects)
           ^^^^^^^^^^^^^^^^^^^^^^^^^^^^^^^^^^^^^^^^^^^^^^^^^^^^^^^^^^^^^^^^^^^^^^
  File "/data/data/com.termux/files/usr/lib/python3.12/site-packages/httpx/_client.py", line 1629, in send
    response = await self._send_handling_auth(
               ^^^^^^^^^^^^^^^^^^^^^^^^^^^^^^^
  File "/data/data/com.termux/files/usr/lib/python3.12/site-packages/httpx/_client.py", line 1657, in _send_handling_auth
    response = await self._send_handling_redirects(
               ^^^^^^^^^^^^^^^^^^^^^^^^^^^^^^^^^^^^
  File "/data/data/com.termux/files/usr/lib/python3.12/site-packages/httpx/_client.py", line 1694, in _send_handling_redirects
    response = await self._send_single_request(request)
               ^^^^^^^^^^^^^^^^^^^^^^^^^^^^^^^^^^^^^^^^
  File "/data/data/com.termux/files/usr/lib/python3.12/site-packages/httpx/_client.py", line 1730, in _send_single_request
    response = await transport.handle_async_request(request)
               ^^^^^^^^^^^^^^^^^^^^^^^^^^^^^^^^^^^^^^^^^^^^^
  File "/data/data/com.termux/files/usr/lib/python3.12/site-packages/httpx/_transports/default.py", line 393, in handle_async_request
    with map_httpcore_exceptions():
         ^^^^^^^^^^^^^^^^^^^^^^^^^
  File "/data/data/com.termux/files/usr/lib/python3.12/contextlib.py", line 158, in __exit__
    self.gen.throw(value)
  File "/data/data/com.termux/files/usr/lib/python3.12/site-packages/httpx/_transports/default.py", line 118, in map_httpcore_exceptions
    raise mapped_exc(message) from exc
httpx.ConnectError: [Errno 7] No address associated with hostname

The above exception was the direct cause of the following exception:

Traceback (most recent call last):
  File "/data/data/com.termux/files/usr/lib/python3.12/site-packages/telegram/ext/_utils/networkloop.py", line 115, in network_retry_loop
    if not await do_action():
           ^^^^^^^^^^^^^^^^^
  File "/data/data/com.termux/files/usr/lib/python3.12/site-packages/telegram/ext/_utils/networkloop.py", line 108, in do_action
    return action_cb_task.result()
           ^^^^^^^^^^^^^^^^^^^^^^^
  File "/data/data/com.termux/files/usr/lib/python3.12/site-packages/telegram/ext/_updater.py", line 335, in polling_action_cb
    updates = await self.bot.get_updates(
              ^^^^^^^^^^^^^^^^^^^^^^^^^^^
  File "/data/data/com.termux/files/usr/lib/python3.12/site-packages/telegram/ext/_extbot.py", line 658, in get_updates
    updates = await super().get_updates(
              ^^^^^^^^^^^^^^^^^^^^^^^^^^
  File "/data/data/com.termux/files/usr/lib/python3.12/site-packages/telegram/_bot.py", line 4593, in get_updates
    await self._post(
  File "/data/data/com.termux/files/usr/lib/python3.12/site-packages/telegram/_bot.py", line 691, in _post
    return await self._do_post(
           ^^^^^^^^^^^^^^^^^^^^
  File "/data/data/com.termux/files/usr/lib/python3.12/site-packages/telegram/ext/_extbot.py", line 362, in _do_post
    return await super()._do_post(
           ^^^^^^^^^^^^^^^^^^^^^^^
  File "/data/data/com.termux/files/usr/lib/python3.12/site-packages/telegram/_bot.py", line 720, in _do_post
    result = await request.post(
             ^^^^^^^^^^^^^^^^^^^
  File "/data/data/com.termux/files/usr/lib/python3.12/site-packages/telegram/request/_baserequest.py", line 197, in post
    result = await self._request_wrapper(
             ^^^^^^^^^^^^^^^^^^^^^^^^^^^^
  File "/data/data/com.termux/files/usr/lib/python3.12/site-packages/telegram/request/_baserequest.py", line 304, in _request_wrapper
    code, payload = await self.do_request(
                    ^^^^^^^^^^^^^^^^^^^^^^
  File "/data/data/com.termux/files/usr/lib/python3.12/site-packages/telegram/request/_httpxrequest.py", line 301, in do_request
    raise NetworkError(f"httpx.{err.__class__.__name__}: {err}") from err
telegram.error.NetworkError: httpx.ConnectError: [Errno 7] No address associated with hostname
2025-03-30 19:24:44,749 - __main__ - ERROR - Exception while handling update:
Traceback (most recent call last):
  File "/data/data/com.termux/files/usr/lib/python3.12/site-packages/httpx/_transports/default.py", line 101, in map_httpcore_exceptions
    yield
  File "/data/data/com.termux/files/usr/lib/python3.12/site-packages/httpx/_transports/default.py", line 394, in handle_async_request
    resp = await self._pool.handle_async_request(req)
           ^^^^^^^^^^^^^^^^^^^^^^^^^^^^^^^^^^^^^^^^^^
  File "/data/data/com.termux/files/usr/lib/python3.12/site-packages/httpcore/_async/connection_pool.py", line 256, in handle_async_request
    raise exc from None
  File "/data/data/com.termux/files/usr/lib/python3.12/site-packages/httpcore/_async/connection_pool.py", line 236, in handle_async_request
    response = await connection.handle_async_request(
               ^^^^^^^^^^^^^^^^^^^^^^^^^^^^^^^^^^^^^^
  File "/data/data/com.termux/files/usr/lib/python3.12/site-packages/httpcore/_async/connection.py", line 101, in handle_async_request
    raise exc
  File "/data/data/com.termux/files/usr/lib/python3.12/site-packages/httpcore/_async/connection.py", line 78, in handle_async_request
    stream = await self._connect(request)
             ^^^^^^^^^^^^^^^^^^^^^^^^^^^^
  File "/data/data/com.termux/files/usr/lib/python3.12/site-packages/httpcore/_async/connection.py", line 124, in _connect
    stream = await self._network_backend.connect_tcp(**kwargs)
             ^^^^^^^^^^^^^^^^^^^^^^^^^^^^^^^^^^^^^^^^^^^^^^^^^
  File "/data/data/com.termux/files/usr/lib/python3.12/site-packages/httpcore/_backends/auto.py", line 31, in connect_tcp
    return await self._backend.connect_tcp(
           ^^^^^^^^^^^^^^^^^^^^^^^^^^^^^^^^
  File "/data/data/com.termux/files/usr/lib/python3.12/site-packages/httpcore/_backends/anyio.py", line 113, in connect_tcp
    with map_exceptions(exc_map):
         ^^^^^^^^^^^^^^^^^^^^^^^
  File "/data/data/com.termux/files/usr/lib/python3.12/contextlib.py", line 158, in __exit__
    self.gen.throw(value)
  File "/data/data/com.termux/files/usr/lib/python3.12/site-packages/httpcore/_exceptions.py", line 14, in map_exceptions
    raise to_exc(exc) from exc
httpcore.ConnectError: [Errno 7] No address associated with hostname

The above exception was the direct cause of the following exception:

Traceback (most recent call last):
  File "/data/data/com.termux/files/usr/lib/python3.12/site-packages/telegram/request/_httpxrequest.py", line 277, in do_request
    res = await self._client.request(
          ^^^^^^^^^^^^^^^^^^^^^^^^^^^
  File "/data/data/com.termux/files/usr/lib/python3.12/site-packages/httpx/_client.py", line 1540, in request
    return await self.send(request, auth=auth, follow_redirects=follow_redirects)
           ^^^^^^^^^^^^^^^^^^^^^^^^^^^^^^^^^^^^^^^^^^^^^^^^^^^^^^^^^^^^^^^^^^^^^^
  File "/data/data/com.termux/files/usr/lib/python3.12/site-packages/httpx/_client.py", line 1629, in send
    response = await self._send_handling_auth(
               ^^^^^^^^^^^^^^^^^^^^^^^^^^^^^^^
  File "/data/data/com.termux/files/usr/lib/python3.12/site-packages/httpx/_client.py", line 1657, in _send_handling_auth
    response = await self._send_handling_redirects(
               ^^^^^^^^^^^^^^^^^^^^^^^^^^^^^^^^^^^^
  File "/data/data/com.termux/files/usr/lib/python3.12/site-packages/httpx/_client.py", line 1694, in _send_handling_redirects
    response = await self._send_single_request(request)
               ^^^^^^^^^^^^^^^^^^^^^^^^^^^^^^^^^^^^^^^^
  File "/data/data/com.termux/files/usr/lib/python3.12/site-packages/httpx/_client.py", line 1730, in _send_single_request
    response = await transport.handle_async_request(request)
               ^^^^^^^^^^^^^^^^^^^^^^^^^^^^^^^^^^^^^^^^^^^^^
  File "/data/data/com.termux/files/usr/lib/python3.12/site-packages/httpx/_transports/default.py", line 393, in handle_async_request
    with map_httpcore_exceptions():
         ^^^^^^^^^^^^^^^^^^^^^^^^^
  File "/data/data/com.termux/files/usr/lib/python3.12/contextlib.py", line 158, in __exit__
    self.gen.throw(value)
  File "/data/data/com.termux/files/usr/lib/python3.12/site-packages/httpx/_transports/default.py", line 118, in map_httpcore_exceptions
    raise mapped_exc(message) from exc
httpx.ConnectError: [Errno 7] No address associated with hostname

The above exception was the direct cause of the following exception:

Traceback (most recent call last):
  File "/data/data/com.termux/files/usr/lib/python3.12/site-packages/telegram/ext/_utils/networkloop.py", line 115, in network_retry_loop
    if not await do_action():
           ^^^^^^^^^^^^^^^^^
  File "/data/data/com.termux/files/usr/lib/python3.12/site-packages/telegram/ext/_utils/networkloop.py", line 108, in do_action
    return action_cb_task.result()
           ^^^^^^^^^^^^^^^^^^^^^^^
  File "/data/data/com.termux/files/usr/lib/python3.12/site-packages/telegram/ext/_updater.py", line 335, in polling_action_cb
    updates = await self.bot.get_updates(
              ^^^^^^^^^^^^^^^^^^^^^^^^^^^
  File "/data/data/com.termux/files/usr/lib/python3.12/site-packages/telegram/ext/_extbot.py", line 658, in get_updates
    updates = await super().get_updates(
              ^^^^^^^^^^^^^^^^^^^^^^^^^^
  File "/data/data/com.termux/files/usr/lib/python3.12/site-packages/telegram/_bot.py", line 4593, in get_updates
    await self._post(
  File "/data/data/com.termux/files/usr/lib/python3.12/site-packages/telegram/_bot.py", line 691, in _post
    return await self._do_post(
           ^^^^^^^^^^^^^^^^^^^^
  File "/data/data/com.termux/files/usr/lib/python3.12/site-packages/telegram/ext/_extbot.py", line 362, in _do_post
    return await super()._do_post(
           ^^^^^^^^^^^^^^^^^^^^^^^
  File "/data/data/com.termux/files/usr/lib/python3.12/site-packages/telegram/_bot.py", line 720, in _do_post
    result = await request.post(
             ^^^^^^^^^^^^^^^^^^^
  File "/data/data/com.termux/files/usr/lib/python3.12/site-packages/telegram/request/_baserequest.py", line 197, in post
    result = await self._request_wrapper(
             ^^^^^^^^^^^^^^^^^^^^^^^^^^^^
  File "/data/data/com.termux/files/usr/lib/python3.12/site-packages/telegram/request/_baserequest.py", line 304, in _request_wrapper
    code, payload = await self.do_request(
                    ^^^^^^^^^^^^^^^^^^^^^^
  File "/data/data/com.termux/files/usr/lib/python3.12/site-packages/telegram/request/_httpxrequest.py", line 301, in do_request
    raise NetworkError(f"httpx.{err.__class__.__name__}: {err}") from err
telegram.error.NetworkError: httpx.ConnectError: [Errno 7] No address associated with hostname
2025-03-30 19:24:49,821 - __main__ - ERROR - Exception while handling update:
Traceback (most recent call last):
  File "/data/data/com.termux/files/usr/lib/python3.12/site-packages/httpx/_transports/default.py", line 101, in map_httpcore_exceptions
    yield
  File "/data/data/com.termux/files/usr/lib/python3.12/site-packages/httpx/_transports/default.py", line 394, in handle_async_request
    resp = await self._pool.handle_async_request(req)
           ^^^^^^^^^^^^^^^^^^^^^^^^^^^^^^^^^^^^^^^^^^
  File "/data/data/com.termux/files/usr/lib/python3.12/site-packages/httpcore/_async/connection_pool.py", line 256, in handle_async_request
    raise exc from None
  File "/data/data/com.termux/files/usr/lib/python3.12/site-packages/httpcore/_async/connection_pool.py", line 236, in handle_async_request
    response = await connection.handle_async_request(
               ^^^^^^^^^^^^^^^^^^^^^^^^^^^^^^^^^^^^^^
  File "/data/data/com.termux/files/usr/lib/python3.12/site-packages/httpcore/_async/connection.py", line 101, in handle_async_request
    raise exc
  File "/data/data/com.termux/files/usr/lib/python3.12/site-packages/httpcore/_async/connection.py", line 78, in handle_async_request
    stream = await self._connect(request)
             ^^^^^^^^^^^^^^^^^^^^^^^^^^^^
  File "/data/data/com.termux/files/usr/lib/python3.12/site-packages/httpcore/_async/connection.py", line 124, in _connect
    stream = await self._network_backend.connect_tcp(**kwargs)
             ^^^^^^^^^^^^^^^^^^^^^^^^^^^^^^^^^^^^^^^^^^^^^^^^^
  File "/data/data/com.termux/files/usr/lib/python3.12/site-packages/httpcore/_backends/auto.py", line 31, in connect_tcp
    return await self._backend.connect_tcp(
           ^^^^^^^^^^^^^^^^^^^^^^^^^^^^^^^^
  File "/data/data/com.termux/files/usr/lib/python3.12/site-packages/httpcore/_backends/anyio.py", line 113, in connect_tcp
    with map_exceptions(exc_map):
         ^^^^^^^^^^^^^^^^^^^^^^^
  File "/data/data/com.termux/files/usr/lib/python3.12/contextlib.py", line 158, in __exit__
    self.gen.throw(value)
  File "/data/data/com.termux/files/usr/lib/python3.12/site-packages/httpcore/_exceptions.py", line 14, in map_exceptions
    raise to_exc(exc) from exc
httpcore.ConnectError: [Errno 7] No address associated with hostname

The above exception was the direct cause of the following exception:

Traceback (most recent call last):
  File "/data/data/com.termux/files/usr/lib/python3.12/site-packages/telegram/request/_httpxrequest.py", line 277, in do_request
    res = await self._client.request(
          ^^^^^^^^^^^^^^^^^^^^^^^^^^^
  File "/data/data/com.termux/files/usr/lib/python3.12/site-packages/httpx/_client.py", line 1540, in request
    return await self.send(request, auth=auth, follow_redirects=follow_redirects)
           ^^^^^^^^^^^^^^^^^^^^^^^^^^^^^^^^^^^^^^^^^^^^^^^^^^^^^^^^^^^^^^^^^^^^^^
  File "/data/data/com.termux/files/usr/lib/python3.12/site-packages/httpx/_client.py", line 1629, in send
    response = await self._send_handling_auth(
               ^^^^^^^^^^^^^^^^^^^^^^^^^^^^^^^
  File "/data/data/com.termux/files/usr/lib/python3.12/site-packages/httpx/_client.py", line 1657, in _send_handling_auth
    response = await self._send_handling_redirects(
               ^^^^^^^^^^^^^^^^^^^^^^^^^^^^^^^^^^^^
  File "/data/data/com.termux/files/usr/lib/python3.12/site-packages/httpx/_client.py", line 1694, in _send_handling_redirects
    response = await self._send_single_request(request)
               ^^^^^^^^^^^^^^^^^^^^^^^^^^^^^^^^^^^^^^^^
  File "/data/data/com.termux/files/usr/lib/python3.12/site-packages/httpx/_client.py", line 1730, in _send_single_request
    response = await transport.handle_async_request(request)
               ^^^^^^^^^^^^^^^^^^^^^^^^^^^^^^^^^^^^^^^^^^^^^
  File "/data/data/com.termux/files/usr/lib/python3.12/site-packages/httpx/_transports/default.py", line 393, in handle_async_request
    with map_httpcore_exceptions():
         ^^^^^^^^^^^^^^^^^^^^^^^^^
  File "/data/data/com.termux/files/usr/lib/python3.12/contextlib.py", line 158, in __exit__
    self.gen.throw(value)
  File "/data/data/com.termux/files/usr/lib/python3.12/site-packages/httpx/_transports/default.py", line 118, in map_httpcore_exceptions
    raise mapped_exc(message) from exc
httpx.ConnectError: [Errno 7] No address associated with hostname

The above exception was the direct cause of the following exception:

Traceback (most recent call last):
  File "/data/data/com.termux/files/usr/lib/python3.12/site-packages/telegram/ext/_utils/networkloop.py", line 115, in network_retry_loop
    if not await do_action():
           ^^^^^^^^^^^^^^^^^
  File "/data/data/com.termux/files/usr/lib/python3.12/site-packages/telegram/ext/_utils/networkloop.py", line 108, in do_action
    return action_cb_task.result()
           ^^^^^^^^^^^^^^^^^^^^^^^
  File "/data/data/com.termux/files/usr/lib/python3.12/site-packages/telegram/ext/_updater.py", line 335, in polling_action_cb
    updates = await self.bot.get_updates(
              ^^^^^^^^^^^^^^^^^^^^^^^^^^^
  File "/data/data/com.termux/files/usr/lib/python3.12/site-packages/telegram/ext/_extbot.py", line 658, in get_updates
    updates = await super().get_updates(
              ^^^^^^^^^^^^^^^^^^^^^^^^^^
  File "/data/data/com.termux/files/usr/lib/python3.12/site-packages/telegram/_bot.py", line 4593, in get_updates
    await self._post(
  File "/data/data/com.termux/files/usr/lib/python3.12/site-packages/telegram/_bot.py", line 691, in _post
    return await self._do_post(
           ^^^^^^^^^^^^^^^^^^^^
  File "/data/data/com.termux/files/usr/lib/python3.12/site-packages/telegram/ext/_extbot.py", line 362, in _do_post
    return await super()._do_post(
           ^^^^^^^^^^^^^^^^^^^^^^^
  File "/data/data/com.termux/files/usr/lib/python3.12/site-packages/telegram/_bot.py", line 720, in _do_post
    result = await request.post(
             ^^^^^^^^^^^^^^^^^^^
  File "/data/data/com.termux/files/usr/lib/python3.12/site-packages/telegram/request/_baserequest.py", line 197, in post
    result = await self._request_wrapper(
             ^^^^^^^^^^^^^^^^^^^^^^^^^^^^
  File "/data/data/com.termux/files/usr/lib/python3.12/site-packages/telegram/request/_baserequest.py", line 304, in _request_wrapper
    code, payload = await self.do_request(
                    ^^^^^^^^^^^^^^^^^^^^^^
  File "/data/data/com.termux/files/usr/lib/python3.12/site-packages/telegram/request/_httpxrequest.py", line 301, in do_request
    raise NetworkError(f"httpx.{err.__class__.__name__}: {err}") from err
telegram.error.NetworkError: httpx.ConnectError: [Errno 7] No address associated with hostname
2025-03-30 19:24:57,429 - __main__ - ERROR - Exception while handling update:
Traceback (most recent call last):
  File "/data/data/com.termux/files/usr/lib/python3.12/site-packages/httpx/_transports/default.py", line 101, in map_httpcore_exceptions
    yield
  File "/data/data/com.termux/files/usr/lib/python3.12/site-packages/httpx/_transports/default.py", line 394, in handle_async_request
    resp = await self._pool.handle_async_request(req)
           ^^^^^^^^^^^^^^^^^^^^^^^^^^^^^^^^^^^^^^^^^^
  File "/data/data/com.termux/files/usr/lib/python3.12/site-packages/httpcore/_async/connection_pool.py", line 256, in handle_async_request
    raise exc from None
  File "/data/data/com.termux/files/usr/lib/python3.12/site-packages/httpcore/_async/connection_pool.py", line 236, in handle_async_request
    response = await connection.handle_async_request(
               ^^^^^^^^^^^^^^^^^^^^^^^^^^^^^^^^^^^^^^
  File "/data/data/com.termux/files/usr/lib/python3.12/site-packages/httpcore/_async/connection.py", line 101, in handle_async_request
    raise exc
  File "/data/data/com.termux/files/usr/lib/python3.12/site-packages/httpcore/_async/connection.py", line 78, in handle_async_request
    stream = await self._connect(request)
             ^^^^^^^^^^^^^^^^^^^^^^^^^^^^
  File "/data/data/com.termux/files/usr/lib/python3.12/site-packages/httpcore/_async/connection.py", line 124, in _connect
    stream = await self._network_backend.connect_tcp(**kwargs)
             ^^^^^^^^^^^^^^^^^^^^^^^^^^^^^^^^^^^^^^^^^^^^^^^^^
  File "/data/data/com.termux/files/usr/lib/python3.12/site-packages/httpcore/_backends/auto.py", line 31, in connect_tcp
    return await self._backend.connect_tcp(
           ^^^^^^^^^^^^^^^^^^^^^^^^^^^^^^^^
  File "/data/data/com.termux/files/usr/lib/python3.12/site-packages/httpcore/_backends/anyio.py", line 113, in connect_tcp
    with map_exceptions(exc_map):
         ^^^^^^^^^^^^^^^^^^^^^^^
  File "/data/data/com.termux/files/usr/lib/python3.12/contextlib.py", line 158, in __exit__
    self.gen.throw(value)
  File "/data/data/com.termux/files/usr/lib/python3.12/site-packages/httpcore/_exceptions.py", line 14, in map_exceptions
    raise to_exc(exc) from exc
httpcore.ConnectError: [Errno 7] No address associated with hostname

The above exception was the direct cause of the following exception:

Traceback (most recent call last):
  File "/data/data/com.termux/files/usr/lib/python3.12/site-packages/telegram/request/_httpxrequest.py", line 277, in do_request
    res = await self._client.request(
          ^^^^^^^^^^^^^^^^^^^^^^^^^^^
  File "/data/data/com.termux/files/usr/lib/python3.12/site-packages/httpx/_client.py", line 1540, in request
    return await self.send(request, auth=auth, follow_redirects=follow_redirects)
           ^^^^^^^^^^^^^^^^^^^^^^^^^^^^^^^^^^^^^^^^^^^^^^^^^^^^^^^^^^^^^^^^^^^^^^
  File "/data/data/com.termux/files/usr/lib/python3.12/site-packages/httpx/_client.py", line 1629, in send
    response = await self._send_handling_auth(
               ^^^^^^^^^^^^^^^^^^^^^^^^^^^^^^^
  File "/data/data/com.termux/files/usr/lib/python3.12/site-packages/httpx/_client.py", line 1657, in _send_handling_auth
    response = await self._send_handling_redirects(
               ^^^^^^^^^^^^^^^^^^^^^^^^^^^^^^^^^^^^
  File "/data/data/com.termux/files/usr/lib/python3.12/site-packages/httpx/_client.py", line 1694, in _send_handling_redirects
    response = await self._send_single_request(request)
               ^^^^^^^^^^^^^^^^^^^^^^^^^^^^^^^^^^^^^^^^
  File "/data/data/com.termux/files/usr/lib/python3.12/site-packages/httpx/_client.py", line 1730, in _send_single_request
    response = await transport.handle_async_request(request)
               ^^^^^^^^^^^^^^^^^^^^^^^^^^^^^^^^^^^^^^^^^^^^^
  File "/data/data/com.termux/files/usr/lib/python3.12/site-packages/httpx/_transports/default.py", line 393, in handle_async_request
    with map_httpcore_exceptions():
         ^^^^^^^^^^^^^^^^^^^^^^^^^
  File "/data/data/com.termux/files/usr/lib/python3.12/contextlib.py", line 158, in __exit__
    self.gen.throw(value)
  File "/data/data/com.termux/files/usr/lib/python3.12/site-packages/httpx/_transports/default.py", line 118, in map_httpcore_exceptions
    raise mapped_exc(message) from exc
httpx.ConnectError: [Errno 7] No address associated with hostname

The above exception was the direct cause of the following exception:

Traceback (most recent call last):
  File "/data/data/com.termux/files/usr/lib/python3.12/site-packages/telegram/ext/_utils/networkloop.py", line 115, in network_retry_loop
    if not await do_action():
           ^^^^^^^^^^^^^^^^^
  File "/data/data/com.termux/files/usr/lib/python3.12/site-packages/telegram/ext/_utils/networkloop.py", line 108, in do_action
    return action_cb_task.result()
           ^^^^^^^^^^^^^^^^^^^^^^^
  File "/data/data/com.termux/files/usr/lib/python3.12/site-packages/telegram/ext/_updater.py", line 335, in polling_action_cb
    updates = await self.bot.get_updates(
              ^^^^^^^^^^^^^^^^^^^^^^^^^^^
  File "/data/data/com.termux/files/usr/lib/python3.12/site-packages/telegram/ext/_extbot.py", line 658, in get_updates
    updates = await super().get_updates(
              ^^^^^^^^^^^^^^^^^^^^^^^^^^
  File "/data/data/com.termux/files/usr/lib/python3.12/site-packages/telegram/_bot.py", line 4593, in get_updates
    await self._post(
  File "/data/data/com.termux/files/usr/lib/python3.12/site-packages/telegram/_bot.py", line 691, in _post
    return await self._do_post(
           ^^^^^^^^^^^^^^^^^^^^
  File "/data/data/com.termux/files/usr/lib/python3.12/site-packages/telegram/ext/_extbot.py", line 362, in _do_post
    return await super()._do_post(
           ^^^^^^^^^^^^^^^^^^^^^^^
  File "/data/data/com.termux/files/usr/lib/python3.12/site-packages/telegram/_bot.py", line 720, in _do_post
    result = await request.post(
             ^^^^^^^^^^^^^^^^^^^
  File "/data/data/com.termux/files/usr/lib/python3.12/site-packages/telegram/request/_baserequest.py", line 197, in post
    result = await self._request_wrapper(
             ^^^^^^^^^^^^^^^^^^^^^^^^^^^^
  File "/data/data/com.termux/files/usr/lib/python3.12/site-packages/telegram/request/_baserequest.py", line 304, in _request_wrapper
    code, payload = await self.do_request(
                    ^^^^^^^^^^^^^^^^^^^^^^
  File "/data/data/com.termux/files/usr/lib/python3.12/site-packages/telegram/request/_httpxrequest.py", line 301, in do_request
    raise NetworkError(f"httpx.{err.__class__.__name__}: {err}") from err
telegram.error.NetworkError: httpx.ConnectError: [Errno 7] No address associated with hostname
2025-03-30 19:25:08,858 - __main__ - ERROR - Exception while handling update:
Traceback (most recent call last):
  File "/data/data/com.termux/files/usr/lib/python3.12/site-packages/httpx/_transports/default.py", line 101, in map_httpcore_exceptions
    yield
  File "/data/data/com.termux/files/usr/lib/python3.12/site-packages/httpx/_transports/default.py", line 394, in handle_async_request
    resp = await self._pool.handle_async_request(req)
           ^^^^^^^^^^^^^^^^^^^^^^^^^^^^^^^^^^^^^^^^^^
  File "/data/data/com.termux/files/usr/lib/python3.12/site-packages/httpcore/_async/connection_pool.py", line 256, in handle_async_request
    raise exc from None
  File "/data/data/com.termux/files/usr/lib/python3.12/site-packages/httpcore/_async/connection_pool.py", line 236, in handle_async_request
    response = await connection.handle_async_request(
               ^^^^^^^^^^^^^^^^^^^^^^^^^^^^^^^^^^^^^^
  File "/data/data/com.termux/files/usr/lib/python3.12/site-packages/httpcore/_async/connection.py", line 101, in handle_async_request
    raise exc
  File "/data/data/com.termux/files/usr/lib/python3.12/site-packages/httpcore/_async/connection.py", line 78, in handle_async_request
    stream = await self._connect(request)
             ^^^^^^^^^^^^^^^^^^^^^^^^^^^^
  File "/data/data/com.termux/files/usr/lib/python3.12/site-packages/httpcore/_async/connection.py", line 124, in _connect
    stream = await self._network_backend.connect_tcp(**kwargs)
             ^^^^^^^^^^^^^^^^^^^^^^^^^^^^^^^^^^^^^^^^^^^^^^^^^
  File "/data/data/com.termux/files/usr/lib/python3.12/site-packages/httpcore/_backends/auto.py", line 31, in connect_tcp
    return await self._backend.connect_tcp(
           ^^^^^^^^^^^^^^^^^^^^^^^^^^^^^^^^
  File "/data/data/com.termux/files/usr/lib/python3.12/site-packages/httpcore/_backends/anyio.py", line 113, in connect_tcp
    with map_exceptions(exc_map):
         ^^^^^^^^^^^^^^^^^^^^^^^
  File "/data/data/com.termux/files/usr/lib/python3.12/contextlib.py", line 158, in __exit__
    self.gen.throw(value)
  File "/data/data/com.termux/files/usr/lib/python3.12/site-packages/httpcore/_exceptions.py", line 14, in map_exceptions
    raise to_exc(exc) from exc
httpcore.ConnectError: [Errno 7] No address associated with hostname

The above exception was the direct cause of the following exception:

Traceback (most recent call last):
  File "/data/data/com.termux/files/usr/lib/python3.12/site-packages/telegram/request/_httpxrequest.py", line 277, in do_request
    res = await self._client.request(
          ^^^^^^^^^^^^^^^^^^^^^^^^^^^
  File "/data/data/com.termux/files/usr/lib/python3.12/site-packages/httpx/_client.py", line 1540, in request
    return await self.send(request, auth=auth, follow_redirects=follow_redirects)
           ^^^^^^^^^^^^^^^^^^^^^^^^^^^^^^^^^^^^^^^^^^^^^^^^^^^^^^^^^^^^^^^^^^^^^^
  File "/data/data/com.termux/files/usr/lib/python3.12/site-packages/httpx/_client.py", line 1629, in send
    response = await self._send_handling_auth(
               ^^^^^^^^^^^^^^^^^^^^^^^^^^^^^^^
  File "/data/data/com.termux/files/usr/lib/python3.12/site-packages/httpx/_client.py", line 1657, in _send_handling_auth
    response = await self._send_handling_redirects(
               ^^^^^^^^^^^^^^^^^^^^^^^^^^^^^^^^^^^^
  File "/data/data/com.termux/files/usr/lib/python3.12/site-packages/httpx/_client.py", line 1694, in _send_handling_redirects
    response = await self._send_single_request(request)
               ^^^^^^^^^^^^^^^^^^^^^^^^^^^^^^^^^^^^^^^^
  File "/data/data/com.termux/files/usr/lib/python3.12/site-packages/httpx/_client.py", line 1730, in _send_single_request
    response = await transport.handle_async_request(request)
               ^^^^^^^^^^^^^^^^^^^^^^^^^^^^^^^^^^^^^^^^^^^^^
  File "/data/data/com.termux/files/usr/lib/python3.12/site-packages/httpx/_transports/default.py", line 393, in handle_async_request
    with map_httpcore_exceptions():
         ^^^^^^^^^^^^^^^^^^^^^^^^^
  File "/data/data/com.termux/files/usr/lib/python3.12/contextlib.py", line 158, in __exit__
    self.gen.throw(value)
  File "/data/data/com.termux/files/usr/lib/python3.12/site-packages/httpx/_transports/default.py", line 118, in map_httpcore_exceptions
    raise mapped_exc(message) from exc
httpx.ConnectError: [Errno 7] No address associated with hostname

The above exception was the direct cause of the following exception:

Traceback (most recent call last):
  File "/data/data/com.termux/files/usr/lib/python3.12/site-packages/telegram/ext/_utils/networkloop.py", line 115, in network_retry_loop
    if not await do_action():
           ^^^^^^^^^^^^^^^^^
  File "/data/data/com.termux/files/usr/lib/python3.12/site-packages/telegram/ext/_utils/networkloop.py", line 108, in do_action
    return action_cb_task.result()
           ^^^^^^^^^^^^^^^^^^^^^^^
  File "/data/data/com.termux/files/usr/lib/python3.12/site-packages/telegram/ext/_updater.py", line 335, in polling_action_cb
    updates = await self.bot.get_updates(
              ^^^^^^^^^^^^^^^^^^^^^^^^^^^
  File "/data/data/com.termux/files/usr/lib/python3.12/site-packages/telegram/ext/_extbot.py", line 658, in get_updates
    updates = await super().get_updates(
              ^^^^^^^^^^^^^^^^^^^^^^^^^^
  File "/data/data/com.termux/files/usr/lib/python3.12/site-packages/telegram/_bot.py", line 4593, in get_updates
    await self._post(
  File "/data/data/com.termux/files/usr/lib/python3.12/site-packages/telegram/_bot.py", line 691, in _post
    return await self._do_post(
           ^^^^^^^^^^^^^^^^^^^^
  File "/data/data/com.termux/files/usr/lib/python3.12/site-packages/telegram/ext/_extbot.py", line 362, in _do_post
    return await super()._do_post(
           ^^^^^^^^^^^^^^^^^^^^^^^
  File "/data/data/com.termux/files/usr/lib/python3.12/site-packages/telegram/_bot.py", line 720, in _do_post
    result = await request.post(
             ^^^^^^^^^^^^^^^^^^^
  File "/data/data/com.termux/files/usr/lib/python3.12/site-packages/telegram/request/_baserequest.py", line 197, in post
    result = await self._request_wrapper(
             ^^^^^^^^^^^^^^^^^^^^^^^^^^^^
  File "/data/data/com.termux/files/usr/lib/python3.12/site-packages/telegram/request/_baserequest.py", line 304, in _request_wrapper
    code, payload = await self.do_request(
                    ^^^^^^^^^^^^^^^^^^^^^^
  File "/data/data/com.termux/files/usr/lib/python3.12/site-packages/telegram/request/_httpxrequest.py", line 301, in do_request
    raise NetworkError(f"httpx.{err.__class__.__name__}: {err}") from err
telegram.error.NetworkError: httpx.ConnectError: [Errno 7] No address associated with hostname
2025-03-30 19:25:25,977 - __main__ - ERROR - Exception while handling update:
Traceback (most recent call last):
  File "/data/data/com.termux/files/usr/lib/python3.12/site-packages/httpx/_transports/default.py", line 101, in map_httpcore_exceptions
    yield
  File "/data/data/com.termux/files/usr/lib/python3.12/site-packages/httpx/_transports/default.py", line 394, in handle_async_request
    resp = await self._pool.handle_async_request(req)
           ^^^^^^^^^^^^^^^^^^^^^^^^^^^^^^^^^^^^^^^^^^
  File "/data/data/com.termux/files/usr/lib/python3.12/site-packages/httpcore/_async/connection_pool.py", line 256, in handle_async_request
    raise exc from None
  File "/data/data/com.termux/files/usr/lib/python3.12/site-packages/httpcore/_async/connection_pool.py", line 236, in handle_async_request
    response = await connection.handle_async_request(
               ^^^^^^^^^^^^^^^^^^^^^^^^^^^^^^^^^^^^^^
  File "/data/data/com.termux/files/usr/lib/python3.12/site-packages/httpcore/_async/connection.py", line 101, in handle_async_request
    raise exc
  File "/data/data/com.termux/files/usr/lib/python3.12/site-packages/httpcore/_async/connection.py", line 78, in handle_async_request
    stream = await self._connect(request)
             ^^^^^^^^^^^^^^^^^^^^^^^^^^^^
  File "/data/data/com.termux/files/usr/lib/python3.12/site-packages/httpcore/_async/connection.py", line 124, in _connect
    stream = await self._network_backend.connect_tcp(**kwargs)
             ^^^^^^^^^^^^^^^^^^^^^^^^^^^^^^^^^^^^^^^^^^^^^^^^^
  File "/data/data/com.termux/files/usr/lib/python3.12/site-packages/httpcore/_backends/auto.py", line 31, in connect_tcp
    return await self._backend.connect_tcp(
           ^^^^^^^^^^^^^^^^^^^^^^^^^^^^^^^^
  File "/data/data/com.termux/files/usr/lib/python3.12/site-packages/httpcore/_backends/anyio.py", line 113, in connect_tcp
    with map_exceptions(exc_map):
         ^^^^^^^^^^^^^^^^^^^^^^^
  File "/data/data/com.termux/files/usr/lib/python3.12/contextlib.py", line 158, in __exit__
    self.gen.throw(value)
  File "/data/data/com.termux/files/usr/lib/python3.12/site-packages/httpcore/_exceptions.py", line 14, in map_exceptions
    raise to_exc(exc) from exc
httpcore.ConnectError: [Errno 7] No address associated with hostname

The above exception was the direct cause of the following exception:

Traceback (most recent call last):
  File "/data/data/com.termux/files/usr/lib/python3.12/site-packages/telegram/request/_httpxrequest.py", line 277, in do_request
    res = await self._client.request(
          ^^^^^^^^^^^^^^^^^^^^^^^^^^^
  File "/data/data/com.termux/files/usr/lib/python3.12/site-packages/httpx/_client.py", line 1540, in request
    return await self.send(request, auth=auth, follow_redirects=follow_redirects)
           ^^^^^^^^^^^^^^^^^^^^^^^^^^^^^^^^^^^^^^^^^^^^^^^^^^^^^^^^^^^^^^^^^^^^^^
  File "/data/data/com.termux/files/usr/lib/python3.12/site-packages/httpx/_client.py", line 1629, in send
    response = await self._send_handling_auth(
               ^^^^^^^^^^^^^^^^^^^^^^^^^^^^^^^
  File "/data/data/com.termux/files/usr/lib/python3.12/site-packages/httpx/_client.py", line 1657, in _send_handling_auth
    response = await self._send_handling_redirects(
               ^^^^^^^^^^^^^^^^^^^^^^^^^^^^^^^^^^^^
  File "/data/data/com.termux/files/usr/lib/python3.12/site-packages/httpx/_client.py", line 1694, in _send_handling_redirects
    response = await self._send_single_request(request)
               ^^^^^^^^^^^^^^^^^^^^^^^^^^^^^^^^^^^^^^^^
  File "/data/data/com.termux/files/usr/lib/python3.12/site-packages/httpx/_client.py", line 1730, in _send_single_request
    response = await transport.handle_async_request(request)
               ^^^^^^^^^^^^^^^^^^^^^^^^^^^^^^^^^^^^^^^^^^^^^
  File "/data/data/com.termux/files/usr/lib/python3.12/site-packages/httpx/_transports/default.py", line 393, in handle_async_request
    with map_httpcore_exceptions():
         ^^^^^^^^^^^^^^^^^^^^^^^^^
  File "/data/data/com.termux/files/usr/lib/python3.12/contextlib.py", line 158, in __exit__
    self.gen.throw(value)
  File "/data/data/com.termux/files/usr/lib/python3.12/site-packages/httpx/_transports/default.py", line 118, in map_httpcore_exceptions
    raise mapped_exc(message) from exc
httpx.ConnectError: [Errno 7] No address associated with hostname

The above exception was the direct cause of the following exception:

Traceback (most recent call last):
  File "/data/data/com.termux/files/usr/lib/python3.12/site-packages/telegram/ext/_utils/networkloop.py", line 115, in network_retry_loop
    if not await do_action():
           ^^^^^^^^^^^^^^^^^
  File "/data/data/com.termux/files/usr/lib/python3.12/site-packages/telegram/ext/_utils/networkloop.py", line 108, in do_action
    return action_cb_task.result()
           ^^^^^^^^^^^^^^^^^^^^^^^
  File "/data/data/com.termux/files/usr/lib/python3.12/site-packages/telegram/ext/_updater.py", line 335, in polling_action_cb
    updates = await self.bot.get_updates(
              ^^^^^^^^^^^^^^^^^^^^^^^^^^^
  File "/data/data/com.termux/files/usr/lib/python3.12/site-packages/telegram/ext/_extbot.py", line 658, in get_updates
    updates = await super().get_updates(
              ^^^^^^^^^^^^^^^^^^^^^^^^^^
  File "/data/data/com.termux/files/usr/lib/python3.12/site-packages/telegram/_bot.py", line 4593, in get_updates
    await self._post(
  File "/data/data/com.termux/files/usr/lib/python3.12/site-packages/telegram/_bot.py", line 691, in _post
    return await self._do_post(
           ^^^^^^^^^^^^^^^^^^^^
  File "/data/data/com.termux/files/usr/lib/python3.12/site-packages/telegram/ext/_extbot.py", line 362, in _do_post
    return await super()._do_post(
           ^^^^^^^^^^^^^^^^^^^^^^^
  File "/data/data/com.termux/files/usr/lib/python3.12/site-packages/telegram/_bot.py", line 720, in _do_post
    result = await request.post(
             ^^^^^^^^^^^^^^^^^^^
  File "/data/data/com.termux/files/usr/lib/python3.12/site-packages/telegram/request/_baserequest.py", line 197, in post
    result = await self._request_wrapper(
             ^^^^^^^^^^^^^^^^^^^^^^^^^^^^
  File "/data/data/com.termux/files/usr/lib/python3.12/site-packages/telegram/request/_baserequest.py", line 304, in _request_wrapper
    code, payload = await self.do_request(
                    ^^^^^^^^^^^^^^^^^^^^^^
  File "/data/data/com.termux/files/usr/lib/python3.12/site-packages/telegram/request/_httpxrequest.py", line 301, in do_request
    raise NetworkError(f"httpx.{err.__class__.__name__}: {err}") from err
telegram.error.NetworkError: httpx.ConnectError: [Errno 7] No address associated with hostname
